[2024-12-13 17:42:22,264] INFO _log() L225  127.0.0.1 - - [13/Dec/2024 17:42:22] "GET /openapi/static/images/swagger.svg HTTP/1.1" 200 - - call_trace=C:\Users\Ricar\AppData\Local\Programs\Python\Python312\Lib\site-packages\werkzeug\_internal.py L225 
[2024-12-13 17:42:23,181] INFO _log() L225  127.0.0.1 - - [13/Dec/2024 17:42:23] "GET /openapi/swagger HTTP/1.1" 200 - - call_trace=C:\Users\Ricar\AppData\Local\Programs\Python\Python312\Lib\site-packages\werkzeug\_internal.py L225 
[2024-12-13 17:42:23,204] INFO _log() L225  127.0.0.1 - - [13/Dec/2024 17:42:23] "[36mGET /openapi/static/css/swagger-ui.css HTTP/1.1[0m" 304 - - call_trace=C:\Users\Ricar\AppData\Local\Programs\Python\Python312\Lib\site-packages\werkzeug\_internal.py L225 
[2024-12-13 17:42:23,205] INFO _log() L225  127.0.0.1 - - [13/Dec/2024 17:42:23] "[36mGET /openapi/static/js/swagger-ui-bundle.js HTTP/1.1[0m" 304 - - call_trace=C:\Users\Ricar\AppData\Local\Programs\Python\Python312\Lib\site-packages\werkzeug\_internal.py L225 
[2024-12-13 17:42:23,206] INFO _log() L225  127.0.0.1 - - [13/Dec/2024 17:42:23] "[36mGET /openapi/static/js/swagger-ui-standalone-preset.js HTTP/1.1[0m" 304 - - call_trace=C:\Users\Ricar\AppData\Local\Programs\Python\Python312\Lib\site-packages\werkzeug\_internal.py L225 
[2024-12-13 17:42:23,297] INFO _log() L225  127.0.0.1 - - [13/Dec/2024 17:42:23] "GET /openapi/openapi.json HTTP/1.1" 200 - - call_trace=C:\Users\Ricar\AppData\Local\Programs\Python\Python312\Lib\site-packages\werkzeug\_internal.py L225 
[2024-12-13 17:42:32,857] WARNING del_produtor() L78   Erro ao deletar produtor #'Teste', Produto não encontrado na base :/ - call_trace=C:\Users\Ricar\OneDrive\Área de Trabalho\Faculdade\Pos\MVP\Projeto\back-end\app.py L78  
[2024-12-13 17:42:32,858] INFO _log() L225  127.0.0.1 - - [13/Dec/2024 17:42:32] "[33mDELETE /produtor?nome=Teste HTTP/1.1[0m" 404 - - call_trace=C:\Users\Ricar\AppData\Local\Programs\Python\Python312\Lib\site-packages\werkzeug\_internal.py L225 
[2024-12-13 17:43:05,372] INFO _log() L225  127.0.0.1 - - [13/Dec/2024 17:43:05] "POST /produtor HTTP/1.1" 200 - - call_trace=C:\Users\Ricar\AppData\Local\Programs\Python\Python312\Lib\site-packages\werkzeug\_internal.py L225 
[2024-12-13 17:43:09,798] ERROR log_exception() L1449 Exception on /produtor [POST] - call_trace=C:\Users\Ricar\AppData\Local\Programs\Python\Python312\Lib\site-packages\flask\app.py L1449
Traceback (most recent call last):
  File "C:\Users\Ricar\AppData\Local\Programs\Python\Python312\Lib\site-packages\sqlalchemy\engine\base.py", line 1900, in _execute_context
    self.dialect.do_execute(
  File "C:\Users\Ricar\AppData\Local\Programs\Python\Python312\Lib\site-packages\sqlalchemy\engine\default.py", line 736, in do_execute
    cursor.execute(statement, parameters)
sqlite3.IntegrityError: UNIQUE constraint failed: produtor.CPF

The above exception was the direct cause of the following exception:

Traceback (most recent call last):
  File "C:\Users\Ricar\AppData\Local\Programs\Python\Python312\Lib\site-packages\flask\app.py", line 2073, in wsgi_app
    response = self.full_dispatch_request()
               ^^^^^^^^^^^^^^^^^^^^^^^^^^^^
  File "C:\Users\Ricar\AppData\Local\Programs\Python\Python312\Lib\site-packages\flask\app.py", line 1519, in full_dispatch_request
    rv = self.handle_user_exception(e)
         ^^^^^^^^^^^^^^^^^^^^^^^^^^^^^
  File "C:\Users\Ricar\AppData\Local\Programs\Python\Python312\Lib\site-packages\flask_cors\extension.py", line 165, in wrapped_function
    return cors_after_request(app.make_response(f(*args, **kwargs)))
                                                ^^^^^^^^^^^^^^^^^^
  File "C:\Users\Ricar\AppData\Local\Programs\Python\Python312\Lib\site-packages\flask\app.py", line 1517, in full_dispatch_request
    rv = self.dispatch_request()
         ^^^^^^^^^^^^^^^^^^^^^^^
  File "C:\Users\Ricar\AppData\Local\Programs\Python\Python312\Lib\site-packages\flask\app.py", line 1503, in dispatch_request
    return self.ensure_sync(self.view_functions[rule.endpoint])(**req.view_args)
           ^^^^^^^^^^^^^^^^^^^^^^^^^^^^^^^^^^^^^^^^^^^^^^^^^^^^^^^^^^^^^^^^^^^^^
  File "C:\Users\Ricar\AppData\Local\Programs\Python\Python312\Lib\site-packages\flask_openapi3\scaffold.py", line 191, in wrapper
    resp = _do_wrapper(
           ^^^^^^^^^^^^
  File "C:\Users\Ricar\AppData\Local\Programs\Python\Python312\Lib\site-packages\flask_openapi3\do_wrapper.py", line 135, in _do_wrapper
    response = func(**request_kwargs)
               ^^^^^^^^^^^^^^^^^^^^^^
  File "C:\Users\Ricar\OneDrive\Área de Trabalho\Faculdade\Pos\MVP\Projeto\back-end\app.py", line 52, in add_produto
    session.commit()
  File "C:\Users\Ricar\AppData\Local\Programs\Python\Python312\Lib\site-packages\sqlalchemy\orm\session.py", line 1451, in commit
    self._transaction.commit(_to_root=self.future)
  File "C:\Users\Ricar\AppData\Local\Programs\Python\Python312\Lib\site-packages\sqlalchemy\orm\session.py", line 829, in commit
    self._prepare_impl()
  File "C:\Users\Ricar\AppData\Local\Programs\Python\Python312\Lib\site-packages\sqlalchemy\orm\session.py", line 808, in _prepare_impl
    self.session.flush()
  File "C:\Users\Ricar\AppData\Local\Programs\Python\Python312\Lib\site-packages\sqlalchemy\orm\session.py", line 3386, in flush
    self._flush(objects)
  File "C:\Users\Ricar\AppData\Local\Programs\Python\Python312\Lib\site-packages\sqlalchemy\orm\session.py", line 3525, in _flush
    with util.safe_reraise():
  File "C:\Users\Ricar\AppData\Local\Programs\Python\Python312\Lib\site-packages\sqlalchemy\util\langhelpers.py", line 70, in __exit__
    compat.raise_(
  File "C:\Users\Ricar\AppData\Local\Programs\Python\Python312\Lib\site-packages\sqlalchemy\util\compat.py", line 208, in raise_
    raise exception
  File "C:\Users\Ricar\AppData\Local\Programs\Python\Python312\Lib\site-packages\sqlalchemy\orm\session.py", line 3486, in _flush
    flush_context.execute()
  File "C:\Users\Ricar\AppData\Local\Programs\Python\Python312\Lib\site-packages\sqlalchemy\orm\unitofwork.py", line 456, in execute
    rec.execute(self)
  File "C:\Users\Ricar\AppData\Local\Programs\Python\Python312\Lib\site-packages\sqlalchemy\orm\unitofwork.py", line 630, in execute
    util.preloaded.orm_persistence.save_obj(
  File "C:\Users\Ricar\AppData\Local\Programs\Python\Python312\Lib\site-packages\sqlalchemy\orm\persistence.py", line 245, in save_obj
    _emit_insert_statements(
  File "C:\Users\Ricar\AppData\Local\Programs\Python\Python312\Lib\site-packages\sqlalchemy\orm\persistence.py", line 1238, in _emit_insert_statements
    result = connection._execute_20(
             ^^^^^^^^^^^^^^^^^^^^^^^
  File "C:\Users\Ricar\AppData\Local\Programs\Python\Python312\Lib\site-packages\sqlalchemy\engine\base.py", line 1705, in _execute_20
    return meth(self, args_10style, kwargs_10style, execution_options)
           ^^^^^^^^^^^^^^^^^^^^^^^^^^^^^^^^^^^^^^^^^^^^^^^^^^^^^^^^^^^
  File "C:\Users\Ricar\AppData\Local\Programs\Python\Python312\Lib\site-packages\sqlalchemy\sql\elements.py", line 333, in _execute_on_connection
    return connection._execute_clauseelement(
           ^^^^^^^^^^^^^^^^^^^^^^^^^^^^^^^^^^
  File "C:\Users\Ricar\AppData\Local\Programs\Python\Python312\Lib\site-packages\sqlalchemy\engine\base.py", line 1572, in _execute_clauseelement
    ret = self._execute_context(
          ^^^^^^^^^^^^^^^^^^^^^^
  File "C:\Users\Ricar\AppData\Local\Programs\Python\Python312\Lib\site-packages\sqlalchemy\engine\base.py", line 1943, in _execute_context
    self._handle_dbapi_exception(
  File "C:\Users\Ricar\AppData\Local\Programs\Python\Python312\Lib\site-packages\sqlalchemy\engine\base.py", line 2124, in _handle_dbapi_exception
    util.raise_(
  File "C:\Users\Ricar\AppData\Local\Programs\Python\Python312\Lib\site-packages\sqlalchemy\util\compat.py", line 208, in raise_
    raise exception
  File "C:\Users\Ricar\AppData\Local\Programs\Python\Python312\Lib\site-packages\sqlalchemy\engine\base.py", line 1900, in _execute_context
    self.dialect.do_execute(
  File "C:\Users\Ricar\AppData\Local\Programs\Python\Python312\Lib\site-packages\sqlalchemy\engine\default.py", line 736, in do_execute
    cursor.execute(statement, parameters)
sqlalchemy.exc.IntegrityError: (sqlite3.IntegrityError) UNIQUE constraint failed: produtor.CPF
[SQL: INSERT INTO produtor (nome, "CPF", numero, funcao, salario, email, curriculum, data_insercao) VALUES (?, ?, ?, ?, ?, ?, ?, ?)]
[parameters: ('Marcos Werneck', 12345678901, 123456789, 'carregador', 150.0, 'teste@teste.comm', 'linkdolinkedin.com', '2024-12-13 17:42:19.841743')]
(Background on this error at: https://sqlalche.me/e/14/gkpj)
[2024-12-13 17:43:09,840] INFO _log() L225  127.0.0.1 - - [13/Dec/2024 17:43:09] "[35m[1mPOST /produtor HTTP/1.1[0m" 500 - - call_trace=C:\Users\Ricar\AppData\Local\Programs\Python\Python312\Lib\site-packages\werkzeug\_internal.py L225 
