[2024-12-13 17:43:32,019] ERROR log_exception() L1449 Exception on /produtor [GET] - call_trace=C:\Users\Ricar\AppData\Local\Programs\Python\Python312\Lib\site-packages\flask\app.py L1449
Traceback (most recent call last):
  File "C:\Users\Ricar\AppData\Local\Programs\Python\Python312\Lib\site-packages\flask\app.py", line 2073, in wsgi_app
    response = self.full_dispatch_request()
               ^^^^^^^^^^^^^^^^^^^^^^^^^^^^
  File "C:\Users\Ricar\AppData\Local\Programs\Python\Python312\Lib\site-packages\flask\app.py", line 1519, in full_dispatch_request
    rv = self.handle_user_exception(e)
         ^^^^^^^^^^^^^^^^^^^^^^^^^^^^^
  File "C:\Users\Ricar\AppData\Local\Programs\Python\Python312\Lib\site-packages\flask_cors\extension.py", line 165, in wrapped_function
    return cors_after_request(app.make_response(f(*args, **kwargs)))
                                                ^^^^^^^^^^^^^^^^^^
  File "C:\Users\Ricar\AppData\Local\Programs\Python\Python312\Lib\site-packages\flask\app.py", line 1517, in full_dispatch_request
    rv = self.dispatch_request()
         ^^^^^^^^^^^^^^^^^^^^^^^
  File "C:\Users\Ricar\AppData\Local\Programs\Python\Python312\Lib\site-packages\flask\app.py", line 1503, in dispatch_request
    return self.ensure_sync(self.view_functions[rule.endpoint])(**req.view_args)
           ^^^^^^^^^^^^^^^^^^^^^^^^^^^^^^^^^^^^^^^^^^^^^^^^^^^^^^^^^^^^^^^^^^^^^
  File "C:\Users\Ricar\AppData\Local\Programs\Python\Python312\Lib\site-packages\flask_openapi3\scaffold.py", line 109, in wrapper
    resp = _do_wrapper(
           ^^^^^^^^^^^^
  File "C:\Users\Ricar\AppData\Local\Programs\Python\Python312\Lib\site-packages\flask_openapi3\do_wrapper.py", line 135, in _do_wrapper
    response = func(**request_kwargs)
               ^^^^^^^^^^^^^^^^^^^^^^
  File "C:\Users\Ricar\OneDrive\Área de Trabalho\Faculdade\Pos\MVP\Projeto\back-end\app.py", line 113, in get_produtor
    return produtor.apresenta_produtor(produtor), 200
           ^^^^^^^^^^^^^^^^^^^^^^^^^^^
AttributeError: 'Query' object has no attribute 'apresenta_produtor'
[2024-12-13 17:43:32,033] INFO _log() L225  127.0.0.1 - - [13/Dec/2024 17:43:32] "[35m[1mGET /produtor?nome=Marcos%20Werneck HTTP/1.1[0m" 500 - - call_trace=C:\Users\Ricar\AppData\Local\Programs\Python\Python312\Lib\site-packages\werkzeug\_internal.py L225 
[2024-12-13 17:44:23,088] ERROR log_exception() L1449 Exception on /produtor [GET] - call_trace=C:\Users\Ricar\AppData\Local\Programs\Python\Python312\Lib\site-packages\flask\app.py L1449
Traceback (most recent call last):
  File "C:\Users\Ricar\AppData\Local\Programs\Python\Python312\Lib\site-packages\flask\app.py", line 2073, in wsgi_app
    response = self.full_dispatch_request()
               ^^^^^^^^^^^^^^^^^^^^^^^^^^^^
  File "C:\Users\Ricar\AppData\Local\Programs\Python\Python312\Lib\site-packages\flask\app.py", line 1519, in full_dispatch_request
    rv = self.handle_user_exception(e)
         ^^^^^^^^^^^^^^^^^^^^^^^^^^^^^
  File "C:\Users\Ricar\AppData\Local\Programs\Python\Python312\Lib\site-packages\flask_cors\extension.py", line 165, in wrapped_function
    return cors_after_request(app.make_response(f(*args, **kwargs)))
                                                ^^^^^^^^^^^^^^^^^^
  File "C:\Users\Ricar\AppData\Local\Programs\Python\Python312\Lib\site-packages\flask\app.py", line 1517, in full_dispatch_request
    rv = self.dispatch_request()
         ^^^^^^^^^^^^^^^^^^^^^^^
  File "C:\Users\Ricar\AppData\Local\Programs\Python\Python312\Lib\site-packages\flask\app.py", line 1503, in dispatch_request
    return self.ensure_sync(self.view_functions[rule.endpoint])(**req.view_args)
           ^^^^^^^^^^^^^^^^^^^^^^^^^^^^^^^^^^^^^^^^^^^^^^^^^^^^^^^^^^^^^^^^^^^^^
  File "C:\Users\Ricar\AppData\Local\Programs\Python\Python312\Lib\site-packages\flask_openapi3\scaffold.py", line 109, in wrapper
    resp = _do_wrapper(
           ^^^^^^^^^^^^
  File "C:\Users\Ricar\AppData\Local\Programs\Python\Python312\Lib\site-packages\flask_openapi3\do_wrapper.py", line 135, in _do_wrapper
    response = func(**request_kwargs)
               ^^^^^^^^^^^^^^^^^^^^^^
  File "C:\Users\Ricar\OneDrive\Área de Trabalho\Faculdade\Pos\MVP\Projeto\back-end\app.py", line 113, in get_produtor
    return produtor.apresenta_produtor(produtor), 200
           ^^^^^^^^^^^^^^^^^^^^^^^^^^^
AttributeError: 'Query' object has no attribute 'apresenta_produtor'
[2024-12-13 17:44:23,097] INFO _log() L225  127.0.0.1 - - [13/Dec/2024 17:44:23] "[35m[1mGET /produtor?nome=%22Marcos%20Werneck%22 HTTP/1.1[0m" 500 - - call_trace=C:\Users\Ricar\AppData\Local\Programs\Python\Python312\Lib\site-packages\werkzeug\_internal.py L225 
[2024-12-13 17:44:27,508] ERROR log_exception() L1449 Exception on /produtor [GET] - call_trace=C:\Users\Ricar\AppData\Local\Programs\Python\Python312\Lib\site-packages\flask\app.py L1449
Traceback (most recent call last):
  File "C:\Users\Ricar\AppData\Local\Programs\Python\Python312\Lib\site-packages\flask\app.py", line 2073, in wsgi_app
    response = self.full_dispatch_request()
               ^^^^^^^^^^^^^^^^^^^^^^^^^^^^
  File "C:\Users\Ricar\AppData\Local\Programs\Python\Python312\Lib\site-packages\flask\app.py", line 1519, in full_dispatch_request
    rv = self.handle_user_exception(e)
         ^^^^^^^^^^^^^^^^^^^^^^^^^^^^^
  File "C:\Users\Ricar\AppData\Local\Programs\Python\Python312\Lib\site-packages\flask_cors\extension.py", line 165, in wrapped_function
    return cors_after_request(app.make_response(f(*args, **kwargs)))
                                                ^^^^^^^^^^^^^^^^^^
  File "C:\Users\Ricar\AppData\Local\Programs\Python\Python312\Lib\site-packages\flask\app.py", line 1517, in full_dispatch_request
    rv = self.dispatch_request()
         ^^^^^^^^^^^^^^^^^^^^^^^
  File "C:\Users\Ricar\AppData\Local\Programs\Python\Python312\Lib\site-packages\flask\app.py", line 1503, in dispatch_request
    return self.ensure_sync(self.view_functions[rule.endpoint])(**req.view_args)
           ^^^^^^^^^^^^^^^^^^^^^^^^^^^^^^^^^^^^^^^^^^^^^^^^^^^^^^^^^^^^^^^^^^^^^
  File "C:\Users\Ricar\AppData\Local\Programs\Python\Python312\Lib\site-packages\flask_openapi3\scaffold.py", line 109, in wrapper
    resp = _do_wrapper(
           ^^^^^^^^^^^^
  File "C:\Users\Ricar\AppData\Local\Programs\Python\Python312\Lib\site-packages\flask_openapi3\do_wrapper.py", line 135, in _do_wrapper
    response = func(**request_kwargs)
               ^^^^^^^^^^^^^^^^^^^^^^
  File "C:\Users\Ricar\OneDrive\Área de Trabalho\Faculdade\Pos\MVP\Projeto\back-end\app.py", line 113, in get_produtor
    return produtor.apresenta_produtor(produtor), 200
           ^^^^^^^^^^^^^^^^^^^^^^^^^^^
AttributeError: 'Query' object has no attribute 'apresenta_produtor'
[2024-12-13 17:44:27,516] INFO _log() L225  127.0.0.1 - - [13/Dec/2024 17:44:27] "[35m[1mGET /produtor?nome=Marcos%20Werneck HTTP/1.1[0m" 500 - - call_trace=C:\Users\Ricar\AppData\Local\Programs\Python\Python312\Lib\site-packages\werkzeug\_internal.py L225 
[2024-12-13 17:44:32,377] ERROR log_exception() L1449 Exception on /produtor [GET] - call_trace=C:\Users\Ricar\AppData\Local\Programs\Python\Python312\Lib\site-packages\flask\app.py L1449
Traceback (most recent call last):
  File "C:\Users\Ricar\AppData\Local\Programs\Python\Python312\Lib\site-packages\flask\app.py", line 2073, in wsgi_app
    response = self.full_dispatch_request()
               ^^^^^^^^^^^^^^^^^^^^^^^^^^^^
  File "C:\Users\Ricar\AppData\Local\Programs\Python\Python312\Lib\site-packages\flask\app.py", line 1519, in full_dispatch_request
    rv = self.handle_user_exception(e)
         ^^^^^^^^^^^^^^^^^^^^^^^^^^^^^
  File "C:\Users\Ricar\AppData\Local\Programs\Python\Python312\Lib\site-packages\flask_cors\extension.py", line 165, in wrapped_function
    return cors_after_request(app.make_response(f(*args, **kwargs)))
                                                ^^^^^^^^^^^^^^^^^^
  File "C:\Users\Ricar\AppData\Local\Programs\Python\Python312\Lib\site-packages\flask\app.py", line 1517, in full_dispatch_request
    rv = self.dispatch_request()
         ^^^^^^^^^^^^^^^^^^^^^^^
  File "C:\Users\Ricar\AppData\Local\Programs\Python\Python312\Lib\site-packages\flask\app.py", line 1503, in dispatch_request
    return self.ensure_sync(self.view_functions[rule.endpoint])(**req.view_args)
           ^^^^^^^^^^^^^^^^^^^^^^^^^^^^^^^^^^^^^^^^^^^^^^^^^^^^^^^^^^^^^^^^^^^^^
  File "C:\Users\Ricar\AppData\Local\Programs\Python\Python312\Lib\site-packages\flask_openapi3\scaffold.py", line 109, in wrapper
    resp = _do_wrapper(
           ^^^^^^^^^^^^
  File "C:\Users\Ricar\AppData\Local\Programs\Python\Python312\Lib\site-packages\flask_openapi3\do_wrapper.py", line 135, in _do_wrapper
    response = func(**request_kwargs)
               ^^^^^^^^^^^^^^^^^^^^^^
  File "C:\Users\Ricar\OneDrive\Área de Trabalho\Faculdade\Pos\MVP\Projeto\back-end\app.py", line 113, in get_produtor
    return produtor.apresenta_produtor(produtor), 200
           ^^^^^^^^^^^^^^^^^^^^^^^^^^^
AttributeError: 'Query' object has no attribute 'apresenta_produtor'
[2024-12-13 17:44:32,385] INFO _log() L225  127.0.0.1 - - [13/Dec/2024 17:44:32] "[35m[1mGET /produtor?nome=Marcos%20Werneck HTTP/1.1[0m" 500 - - call_trace=C:\Users\Ricar\AppData\Local\Programs\Python\Python312\Lib\site-packages\werkzeug\_internal.py L225 
[2024-12-13 17:45:08,560] WARNING del_produtor() L78   Erro ao deletar produtor #'"Marcos Werneck"', Produto não encontrado na base :/ - call_trace=C:\Users\Ricar\OneDrive\Área de Trabalho\Faculdade\Pos\MVP\Projeto\back-end\app.py L78  
[2024-12-13 17:45:08,560] INFO _log() L225  127.0.0.1 - - [13/Dec/2024 17:45:08] "[33mDELETE /produtor?nome=%22Marcos%20Werneck%22 HTTP/1.1[0m" 404 - - call_trace=C:\Users\Ricar\AppData\Local\Programs\Python\Python312\Lib\site-packages\werkzeug\_internal.py L225 
