[2024-12-13 14:31:10,492] ERROR log_exception() L1449 Exception on /fornecedores [GET] - call_trace=C:\Users\Ricar\AppData\Local\Programs\Python\Python312\Lib\site-packages\flask\app.py L1449
Traceback (most recent call last):
  File "C:\Users\Ricar\AppData\Local\Programs\Python\Python312\Lib\site-packages\flask\app.py", line 2073, in wsgi_app
    response = self.full_dispatch_request()
               ^^^^^^^^^^^^^^^^^^^^^^^^^^^^
  File "C:\Users\Ricar\AppData\Local\Programs\Python\Python312\Lib\site-packages\flask\app.py", line 1519, in full_dispatch_request
    rv = self.handle_user_exception(e)
         ^^^^^^^^^^^^^^^^^^^^^^^^^^^^^
  File "C:\Users\Ricar\AppData\Local\Programs\Python\Python312\Lib\site-packages\flask_cors\extension.py", line 165, in wrapped_function
    return cors_after_request(app.make_response(f(*args, **kwargs)))
                                                ^^^^^^^^^^^^^^^^^^
  File "C:\Users\Ricar\AppData\Local\Programs\Python\Python312\Lib\site-packages\flask\app.py", line 1517, in full_dispatch_request
    rv = self.dispatch_request()
         ^^^^^^^^^^^^^^^^^^^^^^^
  File "C:\Users\Ricar\AppData\Local\Programs\Python\Python312\Lib\site-packages\flask\app.py", line 1503, in dispatch_request
    return self.ensure_sync(self.view_functions[rule.endpoint])(**req.view_args)
           ^^^^^^^^^^^^^^^^^^^^^^^^^^^^^^^^^^^^^^^^^^^^^^^^^^^^^^^^^^^^^^^^^^^^^
  File "C:\Users\Ricar\AppData\Local\Programs\Python\Python312\Lib\site-packages\flask_openapi3\scaffold.py", line 109, in wrapper
    resp = _do_wrapper(
           ^^^^^^^^^^^^
  File "C:\Users\Ricar\AppData\Local\Programs\Python\Python312\Lib\site-packages\flask_openapi3\do_wrapper.py", line 135, in _do_wrapper
    response = func(**request_kwargs)
               ^^^^^^^^^^^^^^^^^^^^^^
  File "C:\Users\Ricar\OneDrive\Área de Trabalho\Faculdade\Pos\MVP\Projeto\back-end\app.py", line 142, in get_fornecedores
    fornecedores = session.query(Fornecedor).all()
                   ^^^^^^^^^^^^^^^^^^^^^^^^^
  File "C:\Users\Ricar\AppData\Local\Programs\Python\Python312\Lib\site-packages\sqlalchemy\orm\session.py", line 2159, in query
    return self._query_cls(entities, self, **kwargs)
           ^^^^^^^^^^^^^^^^^^^^^^^^^^^^^^^^^^^^^^^^^
  File "C:\Users\Ricar\AppData\Local\Programs\Python\Python312\Lib\site-packages\sqlalchemy\orm\query.py", line 180, in __init__
    self._set_entities(entities)
  File "C:\Users\Ricar\AppData\Local\Programs\Python\Python312\Lib\site-packages\sqlalchemy\orm\query.py", line 188, in _set_entities
    coercions.expect(
  File "C:\Users\Ricar\AppData\Local\Programs\Python\Python312\Lib\site-packages\sqlalchemy\sql\coercions.py", line 181, in expect
    insp._post_inspect
  File "C:\Users\Ricar\AppData\Local\Programs\Python\Python312\Lib\site-packages\sqlalchemy\util\langhelpers.py", line 1184, in __get__
    obj.__dict__[self.__name__] = result = self.fget(obj)
                                           ^^^^^^^^^^^^^^
  File "C:\Users\Ricar\AppData\Local\Programs\Python\Python312\Lib\site-packages\sqlalchemy\orm\mapper.py", line 2182, in _post_inspect
    self._check_configure()
  File "C:\Users\Ricar\AppData\Local\Programs\Python\Python312\Lib\site-packages\sqlalchemy\orm\mapper.py", line 1924, in _check_configure
    _configure_registries({self.registry}, cascade=True)
  File "C:\Users\Ricar\AppData\Local\Programs\Python\Python312\Lib\site-packages\sqlalchemy\orm\mapper.py", line 3483, in _configure_registries
    _do_configure_registries(registries, cascade)
  File "C:\Users\Ricar\AppData\Local\Programs\Python\Python312\Lib\site-packages\sqlalchemy\orm\mapper.py", line 3518, in _do_configure_registries
    raise e
sqlalchemy.exc.InvalidRequestError: One or more mappers failed to initialize - can't proceed with initialization of other mappers. Triggering mapper: 'mapped class Produtor->produtor'. Original exception was: When initializing mapper mapped class Produtor->produtor, expression 'Comentario' failed to locate a name ('Comentario'). If this is a class name, consider adding this relationship() to the <class 'model.produtor.Produtor'> class after both dependent classes have been defined.
[2024-12-13 14:31:10,493] ERROR log_exception() L1449 Exception on /produtores [GET] - call_trace=C:\Users\Ricar\AppData\Local\Programs\Python\Python312\Lib\site-packages\flask\app.py L1449
Traceback (most recent call last):
  File "C:\Users\Ricar\AppData\Local\Programs\Python\Python312\Lib\site-packages\flask\app.py", line 2073, in wsgi_app
    response = self.full_dispatch_request()
               ^^^^^^^^^^^^^^^^^^^^^^^^^^^^
  File "C:\Users\Ricar\AppData\Local\Programs\Python\Python312\Lib\site-packages\flask\app.py", line 1519, in full_dispatch_request
    rv = self.handle_user_exception(e)
         ^^^^^^^^^^^^^^^^^^^^^^^^^^^^^
  File "C:\Users\Ricar\AppData\Local\Programs\Python\Python312\Lib\site-packages\flask_cors\extension.py", line 165, in wrapped_function
    return cors_after_request(app.make_response(f(*args, **kwargs)))
                                                ^^^^^^^^^^^^^^^^^^
  File "C:\Users\Ricar\AppData\Local\Programs\Python\Python312\Lib\site-packages\flask\app.py", line 1517, in full_dispatch_request
    rv = self.dispatch_request()
         ^^^^^^^^^^^^^^^^^^^^^^^
  File "C:\Users\Ricar\AppData\Local\Programs\Python\Python312\Lib\site-packages\flask\app.py", line 1503, in dispatch_request
    return self.ensure_sync(self.view_functions[rule.endpoint])(**req.view_args)
           ^^^^^^^^^^^^^^^^^^^^^^^^^^^^^^^^^^^^^^^^^^^^^^^^^^^^^^^^^^^^^^^^^^^^^
  File "C:\Users\Ricar\AppData\Local\Programs\Python\Python312\Lib\site-packages\flask_openapi3\scaffold.py", line 109, in wrapper
    resp = _do_wrapper(
           ^^^^^^^^^^^^
  File "C:\Users\Ricar\AppData\Local\Programs\Python\Python312\Lib\site-packages\flask_openapi3\do_wrapper.py", line 135, in _do_wrapper
    response = func(**request_kwargs)
               ^^^^^^^^^^^^^^^^^^^^^^
  File "C:\Users\Ricar\OneDrive\Área de Trabalho\Faculdade\Pos\MVP\Projeto\back-end\app.py", line 98, in get_produtores
    produtores = session.query(Produtor).all()
                 ^^^^^^^^^^^^^^^^^^^^^^^
  File "C:\Users\Ricar\AppData\Local\Programs\Python\Python312\Lib\site-packages\sqlalchemy\orm\session.py", line 2159, in query
    return self._query_cls(entities, self, **kwargs)
           ^^^^^^^^^^^^^^^^^^^^^^^^^^^^^^^^^^^^^^^^^
  File "C:\Users\Ricar\AppData\Local\Programs\Python\Python312\Lib\site-packages\sqlalchemy\orm\query.py", line 180, in __init__
    self._set_entities(entities)
  File "C:\Users\Ricar\AppData\Local\Programs\Python\Python312\Lib\site-packages\sqlalchemy\orm\query.py", line 188, in _set_entities
    coercions.expect(
  File "C:\Users\Ricar\AppData\Local\Programs\Python\Python312\Lib\site-packages\sqlalchemy\sql\coercions.py", line 181, in expect
    insp._post_inspect
  File "C:\Users\Ricar\AppData\Local\Programs\Python\Python312\Lib\site-packages\sqlalchemy\util\langhelpers.py", line 1184, in __get__
    obj.__dict__[self.__name__] = result = self.fget(obj)
                                           ^^^^^^^^^^^^^^
  File "C:\Users\Ricar\AppData\Local\Programs\Python\Python312\Lib\site-packages\sqlalchemy\orm\mapper.py", line 2182, in _post_inspect
    self._check_configure()
  File "C:\Users\Ricar\AppData\Local\Programs\Python\Python312\Lib\site-packages\sqlalchemy\orm\mapper.py", line 1924, in _check_configure
    _configure_registries({self.registry}, cascade=True)
  File "C:\Users\Ricar\AppData\Local\Programs\Python\Python312\Lib\site-packages\sqlalchemy\orm\mapper.py", line 3483, in _configure_registries
    _do_configure_registries(registries, cascade)
  File "C:\Users\Ricar\AppData\Local\Programs\Python\Python312\Lib\site-packages\sqlalchemy\orm\mapper.py", line 3518, in _do_configure_registries
    raise e
sqlalchemy.exc.InvalidRequestError: One or more mappers failed to initialize - can't proceed with initialization of other mappers. Triggering mapper: 'mapped class Produtor->produtor'. Original exception was: When initializing mapper mapped class Produtor->produtor, expression 'Comentario' failed to locate a name ('Comentario'). If this is a class name, consider adding this relationship() to the <class 'model.produtor.Produtor'> class after both dependent classes have been defined.
[2024-12-13 14:31:10,517] INFO _log() L225  127.0.0.1 - - [13/Dec/2024 14:31:10] "[35m[1mGET /eventos HTTP/1.1[0m" 500 - - call_trace=C:\Users\Ricar\AppData\Local\Programs\Python\Python312\Lib\site-packages\werkzeug\_internal.py L225 
[2024-12-13 14:31:10,525] INFO _log() L225  127.0.0.1 - - [13/Dec/2024 14:31:10] "[35m[1mGET /fornecedores HTTP/1.1[0m" 500 - - call_trace=C:\Users\Ricar\AppData\Local\Programs\Python\Python312\Lib\site-packages\werkzeug\_internal.py L225 
[2024-12-13 14:31:10,526] INFO _log() L225  127.0.0.1 - - [13/Dec/2024 14:31:10] "[35m[1mGET /produtores HTTP/1.1[0m" 500 - - call_trace=C:\Users\Ricar\AppData\Local\Programs\Python\Python312\Lib\site-packages\werkzeug\_internal.py L225 
[2024-12-13 14:33:38,365] WARNING _log() L225   * Running on all addresses.
   WARNING: This is a development server. Do not use it in a production deployment. - call_trace=C:\Users\Ricar\AppData\Local\Programs\Python\Python312\Lib\site-packages\werkzeug\_internal.py L225 
[2024-12-13 14:33:38,366] INFO _log() L225   * Running on http://192.168.15.43:5000/ (Press CTRL+C to quit) - call_trace=C:\Users\Ricar\AppData\Local\Programs\Python\Python312\Lib\site-packages\werkzeug\_internal.py L225 
